Workbook
Name WIJI: 'LAPORAN TEKNIK 1 '!$G$134

Sheet Sheet1
A1: LAPORAN KEUANGAN
L2: KAS TAMBAHAN
A4: NO | B4: TANGGAL | C4: KETERANGAN TRANSAKSI | D4: PRAMUDI | E4: BODY | F4: UANG MASUK | G4: UANG KELUAR | H4: SALDO | K4: NO | L4: NAMA | M4: NIK | N4: NOMINAL | O4: KETERANGAN | P4: PEMBAYARAN
A5: 1
A6: 2
A7: 3
A8: 4
A9: 5
A10: 6
A11: 7
A12: 8
A13: 9
A14: 10
A15: 11
A16: 12
... A26: 22
A27: 45870 | H27: 558500 | K27: 45870
A28: 1
A29: 2
A30: 3
A31: 4
A32: 5
A33: 6
A34: 7
A35: 8
A36: 9
A37: 10
A38: 11
A39: 12
... A43: 16
A44: 45901 | H44: 2949500 | K44: 45901
A45: 1
A46: 2
A47: 3
A48: 4
A49: 5
A50: 6
A51: 7
A52: 8
A53: 9
...

Sheet LAPORAN TEKNIK 1 
A1: NO | B1: NAMA ANGGOTA | C1: NIK | D1: JUMLAH PERBAIKAN | E1: JUMLAH PER BULAN | F1: JUMLAH PER BULAN | G1: JUMLAH PER BULAN | H1: JUMLAH PER BULAN | I1: JUMLAH PER BULAN | J1: JUMLAH PER BULAN | K1: JUMLAH PER BULAN | L1: JUMLAH PER BULAN | M1: JUMLAH PER BULAN | N1: JUMLAH PER BULAN | O1: JUMLAH PER BULAN | P1: JUMLAH PER BULAN | Q1: JUMLAH PER BULAN | R1: JUMLAH PER BULAN | S1: JUMLAH PER BULAN | T1: JUMLAH PER BULAN | U1: JUMLAH PER BULAN | V1: JUMLAH PER BULAN | W1: JUMLAH PER ORANG DALAM SETAHUN
D2: APRIL | E2: MEI | H2: JUNI | K2: JULI | N2: AGUSTUS | Q2: SEPTEMBER | T2: OKTOBER
E3: PERBAIKAN | F3: JUMLAH PERBAIKAN | G3: SUKET | H3: PERBAIKAN | I3: JUMLAH PERBAIKAN | J3: SUKET | K3: PERBAIKAN | L3: SPARE PART | M3: SUKET | N3: PERBAIKAN | O3: SPARE PART | P3: SUKET | Q3: PERBAIKAN | R3: SPARE PART | S3: SUKET | T3: PERBAIKAN | U3: SPARE PART | V3: SUKET
A4: 1 | B4: =IFERROR(VLOOKUP(C4,'DAFTAR NAMA PRAMUDI'!C:D,2,FALSE),"0") -> A Sutriadi | C4: 17001137 | E4: 1/5 248 bemper kanan baret | F4: 1 | I4: 0 | Q4: 1
A5: 2 | B5: =IFERROR(VLOOKUP(C5,'DAFTAR NAMA PRAMUDI'!C:D,2,FALSE),"0") -> Abdul Rochman | C5: 17001342 | E5: 18/5 258 bemper kanan baret 17/05/2026 bemper kanan baawah | F5: 2 | I5: 0
A6: 3 | B6: =IFERROR(VLOOKUP(C6,'DAFTAR NAMA PRAMUDI'!C:D,2,FALSE),"0") -> Ade Muhibudin | C6: 17000495 | D6: 27/4 237 body knan gompal | F6: 0 | I6: 0 | Q6: 1
A7: 4 | B7: =IFERROR(VLOOKUP(C7,'DAFTAR NAMA PRAMUDI'!C:D,2,FALSE),"0") -> Ade Tisna | C7: 17000537 | E7: 17/5 273 bemper kanan penyok | F7: 1 | I7: 0 | Q7: 1
A8: 5 | B8: =IFERROR(VLOOKUP(C8,'DAFTAR NAMA PRAMUDI'!C:D,2,FALSE),"0") -> Afrizal Firmansyah | C8: 17001589 | D8: 20/4 274 bemper kanan penyok, body blkng baret | E8: 16/5 266 body blkng kanan baret 26/5 260 kaca samping kanan pecah,kaca pintu blkng pecah,katup emergency pintu blkng pecah | F8: 2 | G8: YA | I8: 0
A9: 6 | B9: =IFERROR(VLOOKUP(C9,'DAFTAR NAMA PRAMUDI'!C:D,2,FALSE),"0") -> Agus Hariyanto | C9: 17001473 | D9: 24/4 255 bemper depan penyok | I9: 0 | Q9: 1
A10: 7 | B10: =IFERROR(VLOOKUP(C10,'DAFTAR NAMA PRAMUDI'!C:D,2,FALSE),"0") -> Agus Sukmana | C10: 17001101 | I10: 0
A11: 8 | B11: =IFERROR(VLOOKUP(C11,'DAFTAR NAMA PRAMUDI'!C:D,2,FALSE),"0") -> Bayu Warastopo | C11: 17001825 | D11: 10/4 252 bemper kanan penyok | E11: 15/5 247 bemper kanan baret | F11: 1 | I11: 0
A12: 9 | B12: =IFERROR(VLOOKUP(C12,'DAFTAR NAMA PRAMUDI'!C:D,2,FALSE),"0") -> Ahmad Gustomi | C12: 17000849 | E12: 5/5 230 bpdy depan kanan atas penyok, cover cctv kanan pecah 11/5 230 bemper kiri penyok | F12: 2 | G12: 2 | H12: VELK Penyok di repair 9 juni 2026 bemper bawah kanan penok 230 | I12: 1 | Q12: 2
A13: 10 | B13: =IFERROR(VLOOKUP(C13,'DAFTAR NAMA PRAMUDI'!C:D,2,FALSE),"0") -> Anang Maulana Awaludin | C13: 17001818 | D13: 6/4 231 bodi blkng baret 7/4 227 bemper depan penyok | F13: 0 | G13: 2 | H13: 15/06/2026 COVER SPION BOLONG .245 | I13: 1
A14: 11 | B14: =IFERROR(VLOOKUP(C14,'DAFTAR NAMA PRAMUDI'!C:D,2,FALSE),"0") -> Akbar | C14: 17001005 | D14: 20/4 266 bemper kanan baret | F14: 0 | G14: 1 | I14: 0
A15: 12 | B15: =IFERROR(VLOOKUP(C15,'DAFTAR NAMA PRAMUDI'!C:D,2,FALSE),"0") -> Andhy Sururi | C15: 17001469 | E15: 10/5 269 bemper kanan baret | F15: 1 | I15: 0
A16: 13 | B16: =IFERROR(VLOOKUP(C16,'DAFTAR NAMA PRAMUDI'!C:D,2,FALSE),"0") -> APIPUDIN | C16: 17001509 | F16: 0 | I16: 0
A17: 14 | B17: =IFERROR(VLOOKUP(C17,'DAFTAR NAMA PRAMUDI'!C:D,2,FALSE),"0") -> Argent Dyego Saragi Napitu | C17: 17001128 | E17: 5/5 271 cover cctv tengah hilang 12/5 261 bemper kanan penyok | F17: 2 | G17: 2 | H17: 3/6 271 body blkng kiri baret 12/06/2026 BEMBER BWG BD 259 | I17: 2
A18: 15 | B18: =IFERROR(VLOOKUP(C18,'DAFTAR NAMA PRAMUDI'!C:D,2,FALSE),"0") -> 0 | C18: 17000678 | F18: 0 | I18: 0 | Q18: 1
A19: 16 | B19: =IFERROR(VLOOKUP(C19,'DAFTAR NAMA PRAMUDI'!C:D,2,FALSE),"0") -> 0 | C19: 17001574 | D19: 14/4 227 cover keong hilang 22/4 227 bemper blkng penyok | F19: 0 | H19: 1/6 227 Bemper kanan penyok | I19: 1
A20: 17 | B20: =IFERROR(VLOOKUP(C20,'DAFTAR NAMA PRAMUDI'!C:D,2,FALSE),"0") -> 0 | C20: 780611296 | F20: 0 | I20: 0
A21: 18 | B21: =IFERROR(VLOOKUP(C21,'DAFTAR NAMA PRAMUDI'!C:D,2,FALSE),"0") -> Bambang irawan | C21: 17001544 | E21: 10/5 258 bemper kanan baret | F21: 1
A22: 19 | B22: =IFERROR(VLOOKUP(C22,'DAFTAR NAMA PRAMUDI'!C:D,2,FALSE),"0") -> Bayu Dyan Sukmana | C22: 17000839 | D22: 13/04/260 bemper kiri depan | E22: 19/5 260 bemper kiri penyok | F22: 1 | G22: 1 | H22: 3/6 266 cover cctv pecah hilang | I22: 1
A23: 20 | B23: =IFERROR(VLOOKUP(C23,'DAFTAR NAMA PRAMUDI'!C:D,2,FALSE),"0") -> Beni S.W | C23: 17000436 | F23: 0 | G23: 1 | I23: 0
A24: 21 | B24: =IFERROR(VLOOKUP(C24,'DAFTAR NAMA PRAMUDI'!C:D,2,FALSE),"0") -> Budi Prasetyo | C24: 17000389 | E24: 31/5 227 body blkng baret | F24: 0 | G24: 1 | I24: 0
A25: 22 | B25: =IFERROR(VLOOKUP(C25,'DAFTAR NAMA PRAMUDI'!C:D,2,FALSE),"0") -> Dede Erik | C25: 17000346 | D25: 21/04 /257 cover cctv hilang/body belakang baret | E25: 5/5 268 bemper kanan depan baret | F25: 1 | G25: 1 | H25: 13/06/2026 spion pecah keong spion ilang 250-226 | I25: 1
A26: 23 | B26: =IFERROR(VLOOKUP(C26,'DAFTAR NAMA PRAMUDI'!C:D,2,FALSE),"0") -> 0 | C26: 17000471 | F26: 0 | H26: MAMAN | I26: 1
A27: 24 | B27: =IFERROR(VLOOKUP(C27,'DAFTAR NAMA PRAMUDI'!C:D,2,FALSE),"0") -> Defi Andri | C27: 7213120708 | D27: 14/4 251 bodi blkng kiri baret | F27: 0 | I27: 0
A28: 25 | B28: =IFERROR(VLOOKUP(C28,'DAFTAR NAMA PRAMUDI'!C:D,2,FALSE),"0") -> Deni Permadi | C28: 17001328 | E28: 4/5 225 cover cctv kiri hilang 7/5 225 bemper kanan baret 12/5 225 bemper kiri penyok | F28: 2 | G28: 3 | I28: 0
A29: 26 | B29: =IFERROR(VLOOKUP(C29,'DAFTAR NAMA PRAMUDI'!C:D,2,FALSE),"0") -> Dodo Wilmar Panjaitan | C29: 17000838 | D29: 26/4 263 bemper kiri penyok | E29: 6/5 263 bemper kanan baret | F29: 1 | I29: 0
A30: 27 | B30: =IFERROR(VLOOKUP(C30,'DAFTAR NAMA PRAMUDI'!C:D,2,FALSE),"0") -> Firman Hari | C30: 17001802 | D30: 1/4 232 bodi blakang baret 5/5 259 bemper kanan penyok 7/4 231 bodi blkng penyok 17/4 248 bemper kanan penyok | E30: 5/5 spion kecil kiri patah, dtabrak TJ 22/5 231 bemper kanan penyok | F30: 2 | G30: 2 | H30: 11 juni 2026 body samping dpan sebelah kiri 249 | I30: 1
A31: 28 | B31: =IFERROR(VLOOKUP(C31,'DAFTAR NAMA PRAMUDI'!C:D,2,FALSE),"0") -> Edy Susanto | C31: 17000427 | D31: 14/4 247 body kanan atas penyok | F31: 0 | H31: 06/06 247 bemper depan kanan bawah | I31: 1
A32: 29 | B32: =IFERROR(VLOOKUP(C32,'DAFTAR NAMA PRAMUDI'!C:D,2,FALSE),"0") -> Efendi | C32: 17000441 | F32: 0 | I32: 0
A33: 30 | B33: =IFERROR(VLOOKUP(C33,'DAFTAR NAMA PRAMUDI'!C:D,2,FALSE),"0") -> Fatah Fathuroji | C33: 17001844 | D33: 4/4 240 body blkng gompal | E33: 12/5 240 body blkng kiri prnyok 31/5 240 body blkng kanan penyok | F33: 2 | G33: 2 | H33: 13/06/2026bemper penyok 240 | I33: 1
A34: 31 | B34: =IFERROR(VLOOKUP(C34,'DAFTAR NAMA PRAMUDI'!C:D,2,FALSE),"0") -> Fahrul Rozi | C34: 17001418 | F34: 0 | I34: 0
A35: 32 | B35: =IFERROR(VLOOKUP(C35,'DAFTAR NAMA PRAMUDI'!C:D,2,FALSE),"0") -> Fajar Miftahudin | C35: 17001576 | D35: 20/4 237 body blkng baret dalam | E35: 5/5 237 body kanan atas penyok | F35: 1 | G35: 1 | I35: 0
A36: 33 | B36: =IFERROR(VLOOKUP(C36,'DAFTAR NAMA PRAMUDI'!C:D,2,FALSE),"0") -> Fernando Triokto Lumbanraja | C36: 17001536 | D36: 21/4 274 bemper kanan penyok 24/4 233 body blkng penyok baret | E36: 16/5 226 kaca spion kanan pecah,cover spion pecah | F36: 1 | G36: 1 | I36: 0
A37: 34 | B37: =IFERROR(VLOOKUP(C37,'DAFTAR NAMA PRAMUDI'!C:D,2,FALSE),"0") -> Gokman S | C37: 17001449 | D37: 18/4 256 bemper kanan penyok | F37: 0 | H37: 06/06/2026 BODY BLAKANG | I37: 1
A38: 35 | B38: =IFERROR(VLOOKUP(C38,'DAFTAR NAMA PRAMUDI'!C:D,2,FALSE),"0") -> 0 | C38: 17001937 | D38: 27/04/249 body baret | E38: 12/5 250 bemper kiri penyok | F38: 1 | G38: 1 | H38: 03/06/244bemper bawah kanan | I38: 0
A39: 36 | B39: =IFERROR(VLOOKUP(C39,'DAFTAR NAMA PRAMUDI'!C:D,2,FALSE),"0") -> Gumilar Aziz Cahyadi | C39: 17001324 | D39: 2/4 261 bemper kanan baret | E39: 15/5 225 bemper kanan baret | F39: 1 | G39: 1 | I39: 0
A40: 37 | B40: =IFERROR(VLOOKUP(C40,'DAFTAR NAMA PRAMUDI'!C:D,2,FALSE),"0") -> Hafid | C40: 17000798 | E40: 13/5 244 bemper kanan baret 19/5 226 bemper kanan baret 27/5 263 bemper kanan penyok | F40: 3 | G40: 3 | I40: 0
...

Sheet Sheet2

Sheet DAFTAR NAMA PRAMUDI
B2: NO | C2: NIK | D2: NAMA
B4: 1 | C4: 17001137 | D4: A Sutriadi
B5: 2 | C5: 17001342 | D5: Abdul Rochman
B6: 3 | C6: 17000495 | D6: Ade Muhibudin
B7: 4 | C7: 17000537 | D7: Ade Tisna
B8: 5 | C8: 17001589 | D8: Afrizal Firmansyah
B9: 6 | C9: 17001473 | D9: Agus Hariyanto
B10: 7 | C10: 17001101 | D10: Agus Sukmana
B11: 8 | C11: 17001814 | D11: Aguswandi
B12: 9 | C12: 17000849 | D12: Ahmad Gustomi
B13: 10 | C13: 17001005 | D13: Akbar
B14: 11 | C14: 17001818 | D14: Anang Maulana Awaludin
B15: 12 | C15: 17001469 | D15: Andhy Sururi
... B126: 123 | C126: 17002098 | D126: ROSARI WULAN PRASASTI
C127: 17001509 | D127: APIPUDIN
C128: 17001447 | D128: HERMAN
C129: 17001903 | D129: WAHYUDI
